Workbook

Sheet A. General Information
A1: A. General Information
A3: A0 | B3: Respondent Information
B4: Name: | D4: Cecila King
B5: Title: | D5: Data Management Coordinator
B6: Office: | D6: Office of Institutional Research and Effectiveness
B7: Mailing Address: | D7: P.O. Drawer EY
B8: City/State/Zip/Country: | D8: Mississippi State, MS 39762 U.S.A.
B9: Phone: | D9: 662-325-3920
B10: Fax: | D10: 662-325-3514
B11: E-mail Address: | D11: oir@ir.msstate.edu
B12: Are your responses to the CDS posted for reference on your institution's Web site? | E12: Yes | F12: No
E13: X
B14: If yes, please provide the URL of the corresponding Web page:
B15: http://www.ir.msstate.edu/
B17: We invite you to indicate if there are items on the CDS for which you cannot use the requested analytic convention, cannot provide data for the cohort requested, whose methodology is unclear, or about which you have questions or comments in general. This information will not be published but will help the publishers further refine CDS items.
A20: A1 | B20: Address Information
B21: Name of College/University: | C21: Mississippi State University
B22: Mailing Address: | C22: P.O. Box 6018
B23: City/State/Zip/Country: | C23: Mississippi State, MS 39762 U.S.A.
B24: Street Address (if different):
B25: City/State/Zip/Country:
B26: Main Phone Number: | C26: 662-325-2323
B27: WWW Home Page Address: | C27: www.msstate.edu
B28: Admissions Phone Number: | C28: 662-325-2224
B29: Admissions Toll-Free Phone Number:
B30: Admissions Office Mailing Address: | C30: P.O. Box 6334
B31: City/State/Zip/Country: | C31: Mississippi State, MS 39762 U.S.A.
B32: Admissions Fax Number: | C32: (662) 325-1MSU
B33: Admissions E-mail Address: | C33: admit@msstate.edu
B34: If there is a separate URL for your school’s online application, please specify: | C34: http://www.msstate.edu/future-students/apply/
B35: If you have a mailing address other than the above to which applications should be sent, please provide:
A37: A2 | B37: Source of institutional control (Check only one):
B38: Public | C38: X
B39: Private (nonprofit)
B40: Proprietary
A42: A3 | B42: Classify your undergraduate institution:
B43: Coeducational college | C43: X
B44: Men's college
B45: Women's college
A47: A4 | B47: Academic year calendar:
...

Sheet B. Enrollment and Persistence
A1: B. ENROLLMENT AND PERSISTENCE
A3: B1 | B3: Institutional Enrollment Men and Women - Provide numbers of students for each of the following categories as of the institution's official fall reporting date.
B4: • Note: Report students formerly designated as “first professional” in the graduate cells.
C6: FULL-TIME | E6: PART-TIME
C7: Men | D7: Women | E7: Men | F7: Women
B8: Undergraduates | H8: men | I8: women | J8: total | L8: ft | M8: pt
B9: Degree-seeking, first-time freshmen | C9: 1612 | D9: 1741 | E9: 6 | F9: 8 | G9: ugrad | H9: =SUM(C9+E9) -> 1618 | I9: =SUM(D9+F9) -> 1749 | J9: =SUM(H9:I9) -> 3367 | L9: =SUM(C9:D9) -> 3353 | M9: =SUM(E9:F9) -> 14
B10: Other first-year, degree-seeking | C10: 822 | D10: 827 | E10: 76 | F10: 104 | H10: =SUM(C10+E10) -> 898 | I10: =SUM(D10+F10) -> 931 | J10: =SUM(H10:I10) -> 1829 | L10: =SUM(C10:D10) -> 1649 | M10: =SUM(E10:F10) -> 180
B11: All other degree-seeking | C11: 5590 | D11: 5785 | E11: 735 | F11: 598 | H11: =SUM(C11+E11) -> 6325 | I11: =SUM(D11+F11) -> 6383 | J11: =SUM(H11:I11) -> 12708 | L11: =SUM(C11:D11) -> 11375 | M11: =SUM(E11:F11) -> 1333
B12: Total degree-seeking | C12: =SUM(C9:C11) -> 8024 | D12: =SUM(D9:D11) -> 8353 | E12: =SUM(E9:E11) -> 817 | F12: =SUM(F9:F11) -> 710 | H12: =SUM(C12+E12) -> 8841 | I12: =SUM(D12+F12) -> 9063 | J12: =SUM(H12:I12) -> 17904 | L12: =SUM(C12:D12) -> 16377 | M12: =SUM(E12:F12) -> 1527
B13: All other undergraduates enrolled in credit courses | C13: 140 | D13: 104 | E13: 85 | F13: 72 | H13: =SUM(C13+E13) -> 225 | I13: =SUM(D13+F13) -> 176 | J13: =SUM(H13:I13) -> 401 | L13: =SUM(C13:D13) -> 244 | M13: =SUM(E13:F13) -> 157
B14: Total undergraduates | C14: =SUM(C12:C13) -> 8164 | D14: =SUM(D12:D13) -> 8457 | E14: =SUM(E12:E13) -> 902 | F14: =SUM(F12:F13) -> 782 | H14: =SUM(C14+E14) -> 9066 | I14: =SUM(D14+F14) -> 9239 | J14: =SUM(H14:I14) -> 18305 | L14: =SUM(C14:D14) -> 16621 | M14: =SUM(E14:F14) -> 1684
B15: Graduate | G15: grad
B16: Degree-seeking, first-time | C16: 182 | D16: 255 | E16: 103 | F16: 114 | H16: =SUM(C16+E16) -> 285 | I16: =SUM(D16+F16) -> 369 | J16: =SUM(H16:I16) -> 654 | L16: =SUM(C16:D16) -> 437 | M16: =SUM(E16:F16) -> 217
B17: All other degree-seeking | C17: 697 | D17: 1003 | E17: 901 | F17: 1014 | H17: =SUM(C17+E17) -> 1598 | I17: =SUM(D17+F17) -> 2017 | J17: =SUM(H17:I17) -> 3615 | L17: =SUM(C17:D17) -> 1700 | M17: =SUM(E17:F17) -> 1915
B18: All other graduates enrolled in credit courses | C18: 1 | D18: 3 | E18: 35 | F18: 36 | H18: =SUM(C18+E18) -> 36 | I18: =SUM(D18+F18) -> 39 | J18: =SUM(H18:I18) -> 75 | L18: =SUM(C18:D18) -> 4 | M18: =SUM(E18:F18) -> 71
B19: Total graduate | C19: =SUM(C16:C18) -> 880 | D19: =SUM(D16:D18) -> 1261 | E19: =SUM(E16:E18) -> 1039 | F19: =SUM(F16:F18) -> 1164 | H19: =SUM(C19+E19) -> 1919 | I19: =SUM(D19+F19) -> 2425 | J19: =SUM(H19:I19) -> 4344 | L19: =SUM(C19:D19) -> 2141 | M19: =SUM(E19:F19) -> 2203
C20: =SUM(C19+C14) -> 9044 | D20: =SUM(D19+D14) -> 9718 | E20: =SUM(E19+E14) -> 1941 | F20: =SUM(F19+F14) -> 1946
B21: Total all undergraduates | C21: =SUM(C14+C19) -> 9044 | D21: =SUM(D14+D19) -> 9718 | E21: =SUM(E14+E19) -> 1941 | F21: =SUM(C14:F14) -> 18305 | H21: =SUM(C14+C19) -> 9044 | I21: =SUM(D14+D19) -> 9718 | J21: =SUM(E14+E19) -> 1941 | K21: =SUM(F14+F19) -> 1946 | L21: =SUM(H21:K21) -> 22649
B22: Total all graduate | F22: =SUM(C19:F19) -> 4344
B23: GRAND TOTAL ALL STUDENTS | F23: =SUM(F21:F22) -> 22649
A25: B2 | B25: Enrollment by Racial/Ethnic Category - Provide numbers of undergraduate students for each of the following categories as of the institution's official fall reporting date.
B26: • Include international students only in the category "Nonresident aliens."
B27: • Complete the “Total Undergraduates” column only if you cannot provide data for the first two columns.
B28: • Report as your institution reports to IPEDS: persons who are Hispanic should be reported only on the Hispanic line, not under any race, and persons who are non-Hispanic multi-racial should be reported only under "Two or more races."
D29: Degree-Seeking First-Time First Year | E29: Degree-Seeking Undergraduates (include first-time first-year) | F29: Total Undergraduates (both degree- and non-degree-seeking)
B30: Nonresident aliens | D30: 36 | E30: 206 | F30: 215
B31: Hispanic/Latino | D31: 130 | E31: 687 | F31: 701
B32: Black or African American, non-Hispanic | D32: 545 | E32: 2721 | F32: 2812
B33: White, non-Hispanic | D33: 2448 | E33: 13322 | F33: 13582
B34: American Indian or Alaska Native, non-Hispanic | D34: 14 | E34: 95 | F34: 96
B35: Asian, non-Hispanic | D35: 59 | E35: 283 | F35: 294
B36: Native Hawaiian or other Pacific Islander, non-Hispanic | D36: 1 | E36: 7 | F36: 9
B37: Two or more races, non-Hispanic | D37: 107 | E37: 460 | F37: 469
B38: Race and/or ethnicity unknown | D38: 27 | E38: 123 | F38: 127
B39: TOTAL | D39: =SUM(D30:D38) -> 3367 | E39: =SUM(E30:E38) -> 17904 | F39: =SUM(F30:F38) -> 18305
B41: Persistence
A42: B3 | B42: Number of degrees awarded from July 1, 2021 to June 30, 2022
B43: Certificate/diploma
B44: Associate degrees
...

Sheet C.First-time Freshmen Admission
A1: C. FIRST-TIME, FIRST-YEAR (FRESHMAN) ADMISSION
B2: Applications
A3: C1 | B3: First-time, first-year, (freshmen) students: Provide the number of degree-seeking, first-time, first-year students who applied, were admitted, and enrolled (full- or part-time) in Fall 2022.
B6: • Include early decision, early action, and students who began studies during summer in this cohort.
B7: • Applicants should include only those students who fulfilled the requirements for consideration for admission (i.e., who completed actionable applications) and who have been notified of one of the following actions: admission, non-admission, placement on waiting list, or application withdrawn (by applicant or institution).
B8: • Admitted applicants should include wait-listed students who were subsequently offered admission.
B9: Total first-time, first-year (freshman) men who applied | E9: 8064 | J9: APPLIED | K9: ADMITTED | L9: ENROLLED
B10: Total first-time, first-year (freshman) women who applied | E10: 10766 | J10: =SUM(E9:E10) -> 18830 | K10: =SUM(E12:E13) -> 14158 | L10: MEN | M10: WOMEN | N10: TOT ENROLLED
L11: =SUM(E15:E16) -> 1618 | M11: =SUM(E18:E19) -> 1749 | N11: =SUM(L11:M11) -> 3367
B12: Total first-time, first-year (freshman) men who were admitted | E12: 6136
B13: Total first-time, first-year (freshman) women who were admitted | E13: 8022
B15: Total full-time, first-time, first-year (freshman) men who enrolled | E15: 1612
B16: Total part-time, first-time, first-year (freshman) men who enrolled | E16: 6
B18: Total full-time, first-time, first-year (freshman) women who enrolled | E18: 1741
B19: Total part-time, first-time, first-year (freshman) women who enrolled | E19: 8
A21: C2 | B21: Freshman wait-listed students
B22: Students who met admission requirements but whose final admission was contingent on space availability
E23: Yes | F23: No
B24: Do you have a policy of placing students on a waiting list? | F24: X
B25: If yes, please answer the questions below for Fall 2022 admissions:
B27: WAITING LIST | E27: TOTAL
B28: Number of qualified applicants offered a place on waiting list
B29: Number accepting a place on the waiting list
B30: Number of wait-listed students admitted
E31: Yes | F31: No
B32: Is your waiting list ranked? | F32: X
B33: If yes, do you release that information to students?
B34: Do you release that information to school counselors?
B36: Admission Requirements
A37: C3 | B37: High school completion requirement
B38: Check the appropriate box to identify your high school completion requirement for degree-seeking entering students:
A39: X | B39: High school diploma is required and GED is accepted
B40: High school diploma is required and GED is not accepted
B41: High school diploma or equivalent is not required
A43: C4 | B43: Does your institution require or recommend a general college-preparatory program for degree-seeking students?
A44: X | B44: Require
B45: Recommend
B46: Neither require nor recommend
A48: C5 | B48: Distribution of high school units required and/or recommended. Specify the distribution of academic high school course units required and/or recommended of all or most degree-seeking students using Carnegie units (one unit equals one year of study or its equivalent). If you use a different system for calculating units, please convert.
D49: Required | E49: Recommended
...

Sheet D. Transfer Admission
A1: D. TRANSFER ADMISSION
B3: Fall Applicants
A4: D1 | F4: Yes | G4: No
B5: Does your institution enroll transfer students? | F5: X
B6: May transfer students earn advanced standing credit by transferring credits earned from course work completed at other colleges/universities? | F6: X
A8: D2 | B8: Provide the number of students who applied, were admitted, and enrolled as degree-seeking transfer students in Fall 2022.
D9: Applicants | E9: Admitted Applicants | F9: Enrolled Applicants
C10: Men | D10: 1722 | E10: 1311 | F10: 898
C11: Women | D11: 2180 | E11: 1454 | F11: 931
C12: Total | D12: =SUM(D10:D11) -> 3902 | E12: =SUM(E10:E11) -> 2765 | F12: =SUM(F10:F11) -> 1829
B14: Application for Admission
A15: D3 | B15: Indicate terms for which transfers may enroll:
A16: X | B16: Fall
B17: Winter
A18: X | B18: Spring
A19: X | B19: Summer
A21: D4 | F21: Yes | G21: No
B22: Must a transfer applicant have a minimum number of credits completed or else must apply as an entering freshman? | G22: X
A24: D5 | B24: Indicate all items required of transfer students to apply for admission:
C25: Required of All | D25: Recommended of All | E25: Recommended of Some | F25: Required of Some | G25: Not Required
B26: High school transcript | F26: X
B27: College transcript(s) | C27: X
B28: Essay or personal statement | G28: X
B29: Interview | G29: X
B30: Standardized test scores | F30: X
B31: Statement of good standing from prior institution(s) | C31: X
A33: D6 | B33: If a minimum high school grade point average is required of transfer applicants, specify (on a 4.0 scale):
A35: D7 | B35: If a minimum college grade point average is required of transfer applicants, specify (on a 4.0 scale): 2.00
A37: D8 | B37: List any other application requirements specific to transfer applicants: | E37: $40 Application Fee
A40: D9 | B40: List application priority, closing, notification, and candidate reply dates for transfer students. If applications are reviewed on a continuous or rolling basis, place a check mark in the “Rolling admission” column.
C41: Priority Date | D41: Closing Date | E41: Notification Date | F41: Reply Date | G41: Rolling Admission
B42: Fall | G42: X
B43: Winter
B44: Spring | G44: X
B45: Summer | G45: X
F47: Yes | G47: No
A48: D10 | B48: Does an open admission policy, if reported, apply to transfer students? | G48: X
A50: D11 | B50: Describe additional requirements for transfer admission, if applicable:
B53: Transfer Credit Policies | G53: Grade
A54: D12 | B54: Report the lowest grade earned for any course that may be transferred for credit: | G54: C *
...

Sheet E. Academic Offerings_Policies
A1: E. ACADEMIC OFFERINGS AND POLICIES
A2: E1 | B2: Special study options: Identify those programs available at your institution. Refer to the glossary for definitions.
A3: X | B3: Accelerated program
A4: X | B4: Cooperative education program
A5: X | B5: Cross-registration
A6: X | B6: Distance learning
A7: X | B7: Double major
A8: X | B8: Dual enrollment
A9: X | B9: English as a Second Language (ESL)
A10: X | B10: Exchange student program (domestic)
B11: External degree program
A12: X | B12: Honors Program
A13: X | B13: Independent study
A14: X | B14: Internships
A15: X | B15: Liberal arts/career combination
A16: X | B16: Student-designed major
A17: X | B17: Study abroad
A18: X | B18: Teacher certification program
B19: Weekend college
B20: Other (specify):
A23: E3 | B23: Areas in which all or most students are required to complete some course work prior to graduation:
A24: X | B24: Arts/fine arts
A25: X | B25: Computer literacy
A26: X | B26: English (including composition)
B27: Foreign languages
A28: X | B28: History
A29: X | B29: Humanities
A30: X | B30: Mathematics
A31: X | B31: Philosophy
A32: X | B32: Sciences (biological or physical)
A33: X | B33: Social science
B34: Other (describe):

Sheet F. Student Life
A1: F. STUDENT LIFE
A3: F1 | B3: Percentages of first-time, first-year (freshman) degree-seeking students and degree-seeking undergraduates enrolled in Fall 2022 who fit the following categories:
F4: First-time Freshmen | G4: Total Undergraduates
B5: Percent who are from out of state (exclude international/nonresident aliens) | F5: =1360/(SUM('B. Enrollment and Persistence'!J9)) -> 0.4039204 | G5: =5688/(SUM('B. Enrollment and Persistence'!J14)) -> 0.31073477
B6: Percent of men who are members of fraternities | F6: =400 / SUM('C.First-time Freshmen Admission'!E15:E16) -> 0.24721879 | G6: =1804/ 'B. Enrollment and Persistence'!H14 -> 0.19898522
B7: Percent of women who are members of sororities | F7: =647 / SUM('C.First-time Freshmen Admission'!E18:E19) -> 0.36992567 | G7: =2386 /'B. Enrollment and Persistence'!I14 -> 0.25825306
B8: Percent who live in college-owned, -operated, or -affiliated housing | F8: =3250/SUM('C.First-time Freshmen Admission'!E15:E19) -> 0.96525097 | G8: =5826/SUM('B. Enrollment and Persistence'!C14:F14) -> 0.3182737
B9: Percent who live off campus or commute | F9: =1-F8 -> 0.034749035 | G9: =1-G8 -> 0.6817263
B10: Percent of students age 25 and older | F10: 0.0021 | G10: 0.0837
B11: Average age of full-time students | F11: 18 | G11: 21
B12: Average age of all students (full- and part-time) | F12: 18 | G12: 21
A14: F2 | B14: Activities offered Identify those programs available at your institution.
A15: X | B15: Campus Ministries
A16: X | B16: Choral groups
A17: X | B17: Concert band
A18: X | B18: Dance
A19: X | B19: Drama/theater
A20: X | B20: International Student Organization
A21: X | B21: Jazz band
A22: X | B22: Literary magazine
A23: X | B23: Marching band
A24: X | B24: Model UN
A25: X | B25: Music ensembles
A26: X | B26: Musical theater
B27: Opera
A28: X | B28: Pep band
A29: X | B29: Radio station
A30: X | B30: Student government
A31: X | B31: Student newspaper
A32: X | B32: Student-run film society
A33: X | B33: Symphony orchestra
A34: X | B34: Television station
B35: Yearbook
A37: F3 | B37: ROTC (program offered in cooperation with Reserve Officers' Training Corps)
E39: On Campus | F39: At Cooperating Institution | G39: Name of Cooperating Institution
B40: Army ROTC is offered: | E40: X
B41: Naval ROTC is offered:
B42: Air Force ROTC is offered: | E42: X
A44: F4 | B44: Housing: Check all types of college-owned, -operated, or -affiliated housing available for undergraduates at your institution.
A45: X | B45: Coed dorms
...

Sheet G. Annual Expenses
A1: G. ANNUAL EXPENSES
A3: G0 | B3: Please provide the URL of your institution’s net price calculator:
B4: https://npc.collegeboard.org/app/msu
B5: Provide 2022-23 academic year costs of attendance for the following categories that are applicable to your institution.
A7: X | B7: Check here if your institution's 2023-24 academic year costs of attendance are not available at this time and provide an approximate date (i.e., month/day) when your institution's final 2023-24 academic year costs of attendance will be available:
B8: 45108
A10: G1 | B10: Undergraduate full-time tuition, required fees, room and board List the typical tuition, required fees, and room and board for a full-time undergraduate student for the FULL 2021-22 academic year (30 semester or 45 quarter hours for institutions that derive annual tuition by multiplying credit hour cost by number of credits).
B12: • A full academic year refers to the period of time generally extending from September to June; usually equated to two semesters, two trimesters, three quarters, or the period covered by a four-one-four plan.
B13: • Room and board is defined as double occupancy and 19 meals per week or the maximum meal plan.
B14: • Required fees include only charges that all full-time students must pay that are not included in tuition (e.g., registration, health, or activity fees.)
B15: • Do not include optional fees (e.g., parking, laboratory use).
B17: PUBLIC INSTITUTIONS | D17: First-Year | E17: Undergraduates
C18: ^Tuition: In-state: | D18: 9248 | E18: 9248
C19: Tuition: Out-of-state: | D19: 25294 | E19: 25294
C20: Tuition: Non-resident alien | D20: 25294 | E20: 25294
B21: FOR ALL INSTITUTIONS
C22: Required Fees | D22: 150 | E22: 150
C23: Room and Board (on-campus): | D23: =SUM(D24:D25) -> 11190 | E23: =SUM(E24:E25) -> 11190
C24: *Room Only (on-campus): | D24: 6822 | E24: 6822
C25: **Board Only (on-campus meal plan): | D25: 4368 | E25: 4368
B27: ^Source: http://www.mississippi.edu/finance/downloads/fy2023_tuition.pdf
B28: *Source: http://www.mississippi.edu/finance/downloads/fy_2021-23_housing.pdf
B29: **Source: http://www.mississippi.edu/finance/downloads/fy_2021-23_meal.pdf
D31: Minimum | E31: Maximum
A32: G2 | B32: Number of credits per term a student can take for the stated full-time tuition | D32: 12
D34: Yes | E34: No
A35: G3 | B35: Do tuition and fees vary by year of study (e.g., sophomore, junior, senior)? | E35: X
D37: Yes | E37: No
A38: G4 | B38: Do tuition and fees vary by undergraduate instructional program? | E38: X
A40: G5 | B40: Provide the estimated expenses for a typical full-time undergraduate student:
C41: Residents | D41: Commuters (living at home) | E41: Commuters (not living at home)
B42: Books and supplies | C42: 1200 | D42: 1200 | E42: 1200
B43: Room only | E43: 6822
B44: Board only | D44: 4368 | E44: 4368
B45: Transportation | C45: 2335 | D45: 2567 | E45: 2335
B46: Other expenses | C46: 3210 | D46: 3210 | E46: 3210
A49: G6 | B49: Undergraduate per-credit-hour charges (tuition only)
B50: ^Tuition: In-state: | C50: 385.5
B51: Tuition: Out-of-state: | C51: 1054.25
B52: Tuition: Non-resident alien | C52: 1054.25

Sheet H. Financial Aid
A1: H. FINANCIAL AID
B3: Aid Awarded to Enrolled Undergraduates
A4: H1 | B4: Enter total dollar amounts awarded to enrolled full-time and less than full-time degree-seeking undergraduates (using the same cohort reported in CDS Question B1, “total degree-seeking” undergraduates) in the following categories.
B5: • If the data being reported are final figures for the 2021-2022 academic year (see the next item below), use the 2021-2022 academic year's CDS Question B1 cohort.
B6: • Include aid awarded to international students (i.e., those not qualifying for federal aid).
B7: • Aid that is non-need-based but that was used to meet need should be reported in the need-based aid column.
B8: • Do NOT include any aid related to the CARES Act or unique to the COVID-19 pandemic.
E10: 2022-2023 estimated | F10: 2021-2022 final
B11: Indicate the academic year for which data are reported for items H1, H2, H2A, and H6 below: | F11: X
B12: Which needs-analysis methodology does your institution use in awarding institutional aid? (Formerly H3)
A14: X | B14: Federal methodology (FM)
B15: Institutional methodology (IM)
B16: Both FM and IM
E18: Need-based $ (Include non-need-based aid used to meet need.) | F18: Non-need-based $ (Exclude non-need-based aid used to meet need.)
B19: Scholarships/Grants
B20: Federal | E20: 43772200
B21: State all states, not only the state in which your institution is located | E21: 10269287 | F21: 2130266
B22: Institutional: Endowed scholarships, annual gifts and tuition funded grants, awarded by the college, excluding athletic aid and tuition waivers (which are reported below). | E22: 39768835 | F22: 27607668
B23: Scholarships/grants from external sources (e.g. Kiwanis, National Merit) not awarded by the college | E23: 9139580 | F23: 3594131
B24: Total Scholarships/Grants | E24: =SUM(E20:E23) -> 102949902 | F24: =SUM(F20:F23) -> 33332065
B25: Self-Help
B26: Student loans from all sources (excluding parent loans) | E26: 84163022 | F26: 17931696
B27: Federal Work-Study | E27: 1530926
B28: State and other (e.g., institutional) work-study/employment (Note: Excludes Federal Work-Study captured above.)
B29: Total Self-Help | E29: =SUM(E26:E28) -> 85693948 | F29: =SUM(F26,F28) -> 17931696
B30: Other
B31: Parent Loans | E31: 13260354 | F31: 7170950
B32: Tuition Waivers Note: Reporting is optional. Report tuition waivers in this row if you choose to report them. Do not report tuition waivers elsewhere. | F32: 81944798
B33: Athletic Awards | F33: 10275804
A35: H2 | B35: Number of Enrolled Students Awarded Aid: List the number of degree-seeking full-time and less-than-full-time undergraduates who applied for and were awarded financial aid from any source.
B36: • Aid that is non-need-based but that was used to meet need should be counted as need- based aid.
B37: • Numbers should reflect the cohort awarded the dollars reported in H1.
B38: • In the chart below, students may be counted in more than one row, and full-time freshmen should also be counted as full-time undergraduates.
B39: • Do NOT include any aid related to the CARES Act or unique to the COVID-19 pandemic.
D41: First-time Full-time Freshmen | E41: Full-time Undergraduate (Incl. Fresh.) | F41: Less Than Full-time Undergraduate
B42: A | C42: Number of degree-seeking undergraduate students (CDS Item B1 if reporting on Fall 2021 cohort) | D42: 3388 | E42: 16794 | F42: 1790
B43: B | C43: Number of students in line a who applied for need-based financial aid | D43: 3038 | E43: 13231 | F43: 990
B44: C | C44: Number of students in line b who were determined to have financial need | D44: 2441 | E44: 11234 | F44: 863
B45: D | C45: Number of students in line c who were awarded any financial aid | D45: 2429 | E45: 11129 | F45: 812
B46: E | C46: Number of students in line d who were awarded any need-based scholarship or grant aid | D46: 2390 | E46: 10702 | F46: 661
...

Sheet I. Instructional Faculty-Class
A1: I. INSTRUCTIONAL FACULTY AND CLASS SIZE
A3: I1 | B3: Please report the number of instructional faculty members in each category for Fall 2022. Include faculty who are on your institution’s payroll on the census date your institution uses for IPEDS/AAUP.
I5: Full-Time | J5: Part-Time | K5: Total
B6: A | C6: Total number of instructional faculty | I6: 1072 | J6: 368 | K6: =SUM(I6:J6) -> 1440 | M6: 1072 | N6: FT Fac | O6: 368 | P6: PT Fac
B7: B | C7: Total number who are members of minority groups | I7: 221 | J7: 82 | K7: =SUM(I7:J7) -> 303 | M7: =O7 -> 122.66667 | N7: 1/3 PT Fac | O7: =O6/3 -> 122.66667 | P7: 1/3 PT Fac
B8: C | C8: Total number who are women | I8: 468 | J8: 197 | K8: =SUM(I8:J8) -> 665 | M8: =SUM(M6:M7) -> 1194.6667
B9: D | C9: Total number who are men | I9: 604 | J9: 171 | K9: =SUM(I9:J9) -> 775
B10: E | C10: Total number who are nonresident aliens (international) | I10: 74 | J10: 4 | K10: =SUM(I10:J10) -> 78
B11: F | C11: Total number with doctorate, or other terminal degree | I11: 889 | J11: 158 | K11: =SUM(I11:J11) -> 1047
B12: G | C12: Total number whose highest degree is a master's but not a terminal master's | I12: 179 | J12: 180 | K12: =SUM(I12:J12) -> 359
B13: H | C13: Total number whose highest degree is a bachelor's | I13: 4 | J13: 18 | K13: =SUM(I13:J13) -> 22
B14: I | C14: Total number whose highest degree is unknown or other (Note: Items f, g, h, and i must sum up to item a.) | I14: 0 | J14: 12 | K14: =SUM(I14:J14) -> 12
B15: J | C15: Total number in stand-alone graduate/ professional programs in which faculty teach virtually only graduate-level students | I15: 0 | J15: 0 | K15: =SUM(I15:J15) -> 0
A17: I2 | B17: Student to Faculty Ratio
B18: Report the Fall 2022 ratio of full-time equivalent students (full-time plus 1/3 part time) to full-time equivalent instructional faculty (full time plus 1/3 part time).
B20: • Exclude both faculty and students in stand-alone graduate or professional programs such as medicine, law, veterinary, dentistry, social work, business, or public health in which faculty teach virtually only graduate-level students.
B21: • Do not count undergraduate or graduate student teaching assistants as faculty.
M22: 18343 | N22: FT Students
B23: Fall 2022 Student to Faculty ratio | G23: =J23/J24 -> 16.426339 | H23: to 1 | I23: (based on | J23: =M24 -> 19624 | K23: students | M23: 1281 | N23: 1/3 PT STUDENTS
I24: and | J24: =M8 -> 1194.6667 | K24: faculty). | M24: =SUM(M22:M23) -> 19624
B26: Instructional Faculty is defined as those members of the instructional-research staff whose major regular assignment is instruction, including those with released time for research. Use the chart below to determine inclusions and exclusions:
J27: Full-time | K27: Part-time
C28: (a) instructional faculty in preclinical and clinical medicine, faculty who are not paid (e.g., those who donate their services or are in the military), or research-only faculty, post-doctoral fellows, or pre-doctoral fellows | J28: Exclude | K28: Include only if they teach one or more non-clinical credit courses
C29: (b) administrative officers with titles such as dean of students, librarian, registrar, coach, and the like, even though they may devote part of their time to classroom instruction and may have faculty status | J29: Exclude | K29: Include if they teach one or more non-clinical credit courses
C30: (c) other administrators/staff who teach one or more non-clinical credit courses even though they do not have faculty status | J30: Exclude | K30: Include
C31: (d) undergraduate or graduate students who assist in the instruction of courses, but have titles such as teaching assistant, teaching fellow, and the like | J31: Exclude | K31: Exclude
C32: (e) faculty on sabbatical or leave with pay | J32: Include | K32: Exclude
C33: (f) faculty on leave without pay | J33: Exclude | K33: Exclude
C34: (g) replacement faculty for faculty on sabbatical leave or leave with pay | J34: Exclude | K34: Include
B36: Full-time instructional faculty: faculty employed on a full-time basis for instruction (including those with released time for research)
B37: Part-time instructional faculty: Adjuncts and other instructors being paid solely for part-time classroom instruction. Also includes full-time faculty teaching less than two semesters, three quarters, two trimesters, or two four-month sessions. Employees who are not considered full-time instructional faculty but who teach one or more non-clinical credit courses may be counted as part-time faculty.
B38: Minority faculty: includes faculty who designate themselves as Black, non-Hispanic; American Indian or Alaska Native; Asian, Native Hawaiian or other Pacific Islander, or Hispanic.
B39: Doctorate: includes such degrees as Doctor of Philosophy, Doctor of Education, Doctor of Juridical Science, and Doctor of Public Health in any field such as arts, sciences, education, engineering, business, and public administration. Also includes terminal degrees formerly designated as “first professional,” including dentistry (DDS or DMD), medicine (MD), optometry (OD), osteopathic medicine (DO), pharmacy (DPharm or BPharm), podiatric medicine (DPM), veterinary medicine (DVM), chiropractic (DC or DCM), or law (JD).
B40: Terminal degree: the highest degree in a field: example, M. Arch (architecture) and MFA (master of fine arts).
A42: I3 | B42: Undergraduate Class Size
B43: In the table below, please use the following definitions to report information about the size of classes and class sections offered in the Fall 2022 term.
B44: • Please include classes that have been moved online in response to the COVID-19 pandemic.
A45: I3 | B45: Number of Class Sections with Undergraduates Enrolled
A47: I3 | B47: Undergraduate Class Size (provide numbers)
A48: I3 | B48: CLASS SECTIONS | D48: 2-9 | E48: 10-19 | F48: 20-29 | G48: 30-39 | H48: 40-49 | I48: 50-99 | J48: 100+ | K48: Total
...

Sheet J. Degrees Conferred
A1: J. DEGREES CONFERRED
A3: J1 | B3: Degrees conferred between July 1, 2021 and June 30, 2022
B4: For each of the following discipline areas, provide the percentage of diplomas/certificates, associate, and bachelor’s degrees awarded.
B5: • To determine the percentage, use majors, not headcount (e.g., students with one degree but a double major will be represented twice).
B6: • Calculate the percentage from your institution’s IPEDS Completions by using the sum of 1st and 2nd majors for each CIP code as the numerator and the sum of the Grand Total by 1st Majors and the Grand Total by 2nd major as the denominator. If you prefer, you can compute the percentages using 1st majors only.
B7: Category | C7: Diploma/Certificates | D7: Associate | E7: Bachelor’s | F7: CIP 2020 Categories to Include | G7: IPEDS 1st Major #
B8: Agriculture | E8: =G8/$G$46 -> 0.05744186 | F8: 01 | G8: 247
B9: Natural resources and conservation | E9: =G9/$G$46 -> 0.026976744 | F9: 03 | G9: 116
B10: Architecture | E10: =G10/$G$46 -> 0.012790698 | F10: 04 | G10: 55
B11: Area, ethnic, and gender studies | E11: =G11/$G$46 -> 0 | F11: 5
B12: Communication/journalism | E12: =G12/$G$46 -> 0.038372093 | F12: 09 | G12: 165
B13: Communication technologies | E13: =G13/$G$46 -> 0 | F13: 10
B14: Computer and information sciences | E14: =G14/$G$46 -> 0.019302326 | F14: 11 | G14: 83
B15: Personal and culinary services | E15: =G15/$G$46 -> 0.0011627907 | F15: 12 | G15: 5
B16: Education | E16: =G16/$G$46 -> 0.082093023 | F16: 13 | G16: 353
B17: Engineering | E17: =G17/$G$46 -> 0.16255814 | F17: 14 | G17: 699
B18: Engineering technologies | E18: =G18/$G$46 -> 0.017906977 | F18: 15 | G18: 77
B19: Foreign languages, literatures, and linguistics | E19: =G19/$G$46 -> 0.0076744186 | F19: 16 | G19: 33
B20: Family and consumer sciences | E20: =G20/$G$46 -> 0.018372093 | F20: 19 | G20: 79
B21: Law/legal studies | E21: =G21/$G$46 -> 0 | F21: 22
B22: English | E22: =G22/$G$46 -> 0.0053488372 | F22: 23 | G22: 23
B23: Liberal arts/general studies | E23: =G23/$G$46 -> 0.013488372 | F23: 24 | G23: 58
B24: Library science | E24: =G24/$G$46 -> 0 | F24: 25
B25: Biological/life sciences | E25: =G25/$G$46 -> 0.067674419 | F25: 26 | G25: 291
B26: Mathematics and statistics | E26: =G26/$G$46 -> 0.008372093 | F26: 27 | G26: 36
B27: Military science and military technologies | E27: =G27/$G$46 -> 0 | F27: 28 & 29
B28: Interdisciplinary studies | E28: =G28/$G$46 -> 0.053023256 | F28: 30 | G28: 228
B29: Parks and recreation | E29: =G29/$G$46 -> 0.059069767 | F29: 31 | G29: 254
B30: Philosophy and religious studies | E30: =G30/$G$46 -> 0.0013953488 | F30: 38 | G30: 6
B31: Theology and religious vocations | E31: =G31/$G$46 -> 0 | F31: 39
B32: Physical sciences | E32: =G32/$G$46 -> 0.026046512 | F32: 40 | G32: 112
B33: Science technologies | E33: =G33/$G$46 -> 0 | F33: 41
B34: Psychology | E34: =G34/$G$46 -> 0.061395349 | F34: 42 | G34: 264
B35: Homeland Security, law enforcement, firefighting, and protective services | E35: =G35/$G$46 -> 0 | F35: 43
B36: Public administration and social services | E36: =G36/$G$46 -> 0.0086046512 | F36: 44 | G36: 37
B37: Social sciences | E37: =G37/$G$46 -> 0.038139535 | F37: 45 | G37: 164
B38: Construction trades | E38: =G38/$G$46 -> 0 | F38: 46
B39: Mechanic and repair technologies | E39: =G39/$G$46 -> 0 | F39: 47
B40: Precision production | E40: =G40/$G$46 -> 0 | F40: 48
B41: Transportation and materials moving | E41: =G41/$G$46 -> 0 | F41: 49
...
